<?xml version="1.0"?>
<!-- copied from Understanding URDF using MATLABR - Peter Corke -->
<robot name="planar2">
  <link name="base_link" />
  <link name="link1" />
  <link name="link2" />
  <link name="end" />
  <joint name="q1" type="continuous">
    <parent link="base_link" />
    <child link="link1" />
    <axis xyz="0 0 1" />
</joint>
  <joint name="q2" type="continuous">
    <parent link="link1" />
    <child link="link2" />
    <origin xyz="1 0 0" />
    <axis xyz="0 0 1" />
  </joint>
  <joint name="notajoint" type="fixed">
    <parent link="link2" />
    <child link="end" />
    <origin xyz="1 0 0" />
  </joint>
</robot>
