<?xml version="1.0" ?>
<!-- =================================================================================== -->
<!-- |    This document was autogenerated by xacro from mini-pupper.urdf.xacro         | -->
<!-- |    EDITING THIS FILE BY HAND IS NOT RECOMMENDED                                 | -->
<!-- =================================================================================== -->
<robot name="mini-pupper">
  <material name="black">
    <color rgba="0.15 0.15 0.15 1.0"/>
  </material>
  <material name="dyellow">
    <color rgba="0.95 0.93 0.13 1.0"/>
  </material>
  <material name="white">
    <color rgba="0.97 0.97 0.97 1.0"/>
  </material>
  <link name="base_link">
    <collision>
      <origin rpy="0 0 0" xyz="0 0 0"/>
      <geometry>
        <mesh filename="../meshes/base.stl" scale="0.001 0.001 0.001"/>
      </geometry>
    </collision>
    <visual>
      <origin rpy="0 0 0" xyz="0 0 0"/>
      <geometry>
        <mesh filename="../meshes/base.stl" scale="1 1 1"/>
      </geometry>
      <material name="dyellow"/>
    </visual>
  </link>
  <link name="base_inertia">
    <inertial>
      <origin xyz="0 0 0"/>
      <mass value="1.0"/>
      <inertia ixx="0.0008166666666666667" ixy="0.0" ixz="0.0" iyy="0.0036096666666666673" iyz="0.0" izz="0.0036096666666666673"/>
    </inertial>
  </link>
  <joint name="base_link_to_base_inertia" type="fixed">
    <parent link="base_link"/>
    <child link="base_inertia"/>
    <origin rpy="0 0 0" xyz="0 0 0"/>
  </joint>
  <!-- 
    <link name="face">
        <inertial>
            <origin xyz="0 0 0" />
            <mass value="0.0" />
            <inertia ixx="0.0" ixy="0.0" ixz="0.0" iyy="0.0" iyz="0.0" izz="0.0" />
        </inertial>
        <visual>
            <geometry>
                <box size="0.005 0.0406 0.031086"/>
            </geometry>
            <origin xyz="0 0 0" rpy="0 0 0"/>
            <material name="black" />
        </visual>
    </link>
    <joint name="base_link_to_face" type="fixed">
        <parent link="base_link"/>
        <child link="face"/>
        <origin xyz="${base_x_length/2 - 0.0015} 0 0.0225" rpy="0 0 0"/>
    </joint>

    <link name="eye_l">
        <inertial>
            <origin xyz="0 0 0" />
            <mass value="0.0" />
            <inertia ixx="0.0" ixy="0.0" ixz="0.0" iyy="0.0" iyz="0.0" izz="0.0" />
        </inertial>
        <visual>
            <geometry>
                <box size="0.005 0.0083 0.014"/>
            </geometry>
            <origin xyz="0 0 0" rpy="0 0 0"/>
            <material name="white" />
        </visual>
    </link>
    <joint name="face_to_eye_l" type="fixed">
        <parent link="face"/>
        <child link="eye_l"/>
        <origin xyz="0.00005 -0.006 0" rpy="0 0 0"/>
    </joint>

    <link name="eye_r">
        <inertial>
            <origin xyz="0 0 0" />
            <mass value="0.0" />
            <inertia ixx="0.0" ixy="0.0" ixz="0.0" iyy="0.0" iyz="0.0" izz="0.0" />
        </inertial>
        <visual>
            <geometry>
                <box size="0.005 0.0083 0.014"/>
            </geometry>
            <origin xyz="0 0 0" rpy="0 0 0"/>
            <material name="white" />
        </visual>
    </link>
    <joint name="face_to_eye_r" type="fixed">
        <parent link="face"/>
        <child link="eye_r"/>
        <origin xyz="0.00005 0.006 0" rpy="0 0 0"/>
    </joint> -->
  <gazebo reference="base_link">
    <material>Gazebo/ZincYellow</material>
  </gazebo>
  <!-- <gazebo reference="face">
        <material>Gazebo/FlatBlack</material>
    </gazebo>

    <gazebo reference="eye_l">
        <material>Gazebo/White</material>
    </gazebo>

    <gazebo reference="eye_r">
        <material>Gazebo/White</material>
    </gazebo> -->
  <!--
    <xacro:include filename="$(find mini-pupper_description)/urdf/accessories.urdf.xacro" />

    <xacro:accessories
        base_name="base_link"
        base_length="${base_x_length}"
        base_height="${base_z_length}"
    />
-->
  <link name="lf_hip_debug_link"/>
  <link name="lf_hip_link">
    <inertial>
      <mass value="0.25"/>
      <inertia ixx="7.298104166666667e-05" ixy="0.0" ixz="0.0" iyy="8.328208333333335e-05" iyz="0.0" izz="8.450270833333332e-05"/>
    </inertial>
    <collision>
      <origin rpy="0 0 0" xyz="0 0 0"/>
      <geometry>
        <mesh filename="../meshes/lf_hip.stl" scale="1 1 1"/>
      </geometry>
    </collision>
    <visual>
      <origin rpy="0 0 0" xyz="0 0 0"/>
      <geometry>
        <mesh filename="../meshes/lf_hip.stl" scale="1 1 1"/>
      </geometry>
      <material name="dyellow"/>
    </visual>
  </link>
  <gazebo reference="lf_hip_link">
    <material>Gazebo/Yellow</material>
  </gazebo>
  <link name="lf_upper_leg_link">
    <inertial>
      <origin xyz="0 0 -0.002375000000000002"/>
      <mass value="0.0625"/>
      <inertia ixx="3.159338020833334e-05" ixy="0.0" ixz="0.0" iyy="3.7282633854166664e-05" iyz="0.0" izz="7.931013020833332e-06"/>
    </inertial>
    <collision>
      <origin rpy="0 0 0" xyz="0 0 0"/>
      <geometry>
        <mesh filename="../meshes/lf_lower_leg.stl" scale="1 1 1"/>
      </geometry>
    </collision>
    <visual>
      <origin rpy="0 0 0" xyz="0 0 0"/>
      <geometry>
        <mesh filename="../meshes/lf_lower_leg.stl" scale="1 1 1"/>
      </geometry>
      <material name="dyellow"/>
    </visual>
  </link>
  <gazebo reference="lf_upper_leg_link">
    <material>Gazebo/Yellow</material>
  </gazebo>
  <link name="lf_lower_leg_link">
    <inertial>
      <origin xyz="0 0 -0.016780000000000003"/>
      <mass value="0.125"/>
      <inertia ixx="6.411545416666666e-05" ixy="0.0" ixz="0.0" iyy="6.491712083333332e-05" iyz="0.0" izz="8.485416666666666e-07"/>
    </inertial>
    <collision>
      <origin rpy="0 0 0" xyz="0 0 0"/>
      <geometry>
        <mesh filename="../meshes/lf_lower_leg.stl" scale="1 1 1"/>
      </geometry>
    </collision>
    <visual>
      <origin rpy="0 0 0" xyz="0 0 0"/>
      <geometry>
        <mesh filename="../meshes/lf_lower_leg.stl" scale="1 1 1"/>
      </geometry>
      <material name="black"/>
    </visual>
  </link>
  <gazebo reference="lf_lower_leg_link">
    <kp>1000000.0</kp>
    <kd>1.0</kd>
    <mu1>0.8</mu1>
    <mu2>0.8</mu2>
    <maxVel>0.0</maxVel>
    <minDepth>0.001</minDepth>
    <material>Gazebo/FlatBlack</material>
  </gazebo>
  <link name="lf_foot_link">
    <inertial>
      <origin xyz="0 0 0"/>
      <mass value="0.0625"/>
      <inertia ixx="2.41921875e-06" ixy="0.0" ixz="0.0" iyy="3.7369270833333336e-06" iyz="0.0" izz="1.6927083333333335e-06"/>
    </inertial>
    <collision>
      <origin rpy="0 0 0" xyz="0 0 0"/>
      <geometry>
        <mesh filename="../meshes/foot.stl" scale="1 1 1"/>
      </geometry>
    </collision>
    <visual>
      <origin rpy="0 0 0" xyz="0 0 0"/>
      <geometry>
        <mesh filename="../meshes/foot.stl" scale="1 1 1"/>
      </geometry>
      <material name="black"/>
    </visual>
  </link>
  <gazebo reference="lf_foot_link">
    <material>Gazebo/FlatBlack</material>
  </gazebo>
  <joint name="lf_debug_joint" type="fixed">
    <parent link="base_link"/>
    <child link="lf_hip_debug_link"/>
    <origin rpy="0 0 0" xyz="0.06014 0.0235 0.0171"/>
  </joint>
  <joint name="lf_hip_joint" type="revolute">
    <axis xyz="1 0 0"/>
    <limit effort="5" lower="-3.141592653589793" upper="3.141592653589793" velocity="2.5"/>
    <parent link="base_link"/>
    <child link="lf_hip_link"/>
    <origin rpy="0 0 0" xyz="0.06014 0.0235 0.0171"/>
  </joint>
  <joint name="lf_upper_leg_joint" type="revolute">
    <axis xyz="0 1 0"/>
    <limit effort="5" lower="-3.141592653589793" upper="3.141592653589793" velocity="2.5"/>
    <parent link="lf_hip_link"/>
    <child link="lf_upper_leg_link"/>
    <origin rpy="0 0 0" xyz="0 0.0197 0"/>
  </joint>
  <joint name="lf_lower_leg_joint" type="revolute">
    <axis xyz="0 1 0"/>
    <limit effort="5" lower="-3.141592653589793" upper="3.141592653589793" velocity="2.5"/>
    <parent link="lf_upper_leg_link"/>
    <child link="lf_lower_leg_link"/>
    <origin rpy="0 0 0" xyz="0 0.00475 -0.05"/>
  </joint>
  <joint name="lf_foot_joint" type="fixed">
    <parent link="lf_lower_leg_link"/>
    <child link="lf_foot_link"/>
    <origin rpy="0 0 0" xyz="0 0 -0.056"/>
  </joint>
  <transmission name="lf_hip_joint_trans">
    <type>transmission_interface/SimpleTransmission</type>
    <joint name="lf_hip_joint">
      <hardwareInterface>hardware_interface/EffortJointInterface</hardwareInterface>
    </joint>
    <actuator name="lf_hip_joint_motor">
      <hardwareInterface>hardware_interface/EffortJointInterface</hardwareInterface>
      <mechanicalReduction>1</mechanicalReduction>
    </actuator>
  </transmission>
  <transmission name="lf_upper_leg_joint_trans">
    <type>transmission_interface/SimpleTransmission</type>
    <joint name="lf_upper_leg_joint">
      <hardwareInterface>hardware_interface/EffortJointInterface</hardwareInterface>
    </joint>
    <actuator name="lf_upper_leg_joint_motor">
      <hardwareInterface>hardware_interface/EffortJointInterface</hardwareInterface>
      <mechanicalReduction>1</mechanicalReduction>
    </actuator>
  </transmission>
  <transmission name="lf_lower_leg_joint_trans">
    <type>transmission_interface/SimpleTransmission</type>
    <joint name="lf_lower_leg_joint">
      <hardwareInterface>hardware_interface/EffortJointInterface</hardwareInterface>
    </joint>
    <actuator name="lf_lower_joint_motor">
      <hardwareInterface>hardware_interface/EffortJointInterface</hardwareInterface>
      <mechanicalReduction>1</mechanicalReduction>
    </actuator>
  </transmission>
  <link name="lh_hip_debug_link"/>
  <link name="lh_hip_link">
    <inertial>
      <mass value="0.25"/>
      <inertia ixx="7.298104166666667e-05" ixy="0.0" ixz="0.0" iyy="8.328208333333335e-05" iyz="0.0" izz="8.450270833333332e-05"/>
    </inertial>
    <collision>
      <origin rpy="0 0 0" xyz="0 0 0"/>
      <geometry>
        <mesh filename="../meshes/lh_hip.stl" scale="1 1 1"/>
      </geometry>
    </collision>
    <visual>
      <origin rpy="0 0 0" xyz="0 0 0"/>
      <geometry>
        <mesh filename="../meshes/lh_hip.stl" scale="1 1 1"/>
      </geometry>
      <material name="dyellow"/>
    </visual>
  </link>
  <gazebo reference="lh_hip_link">
    <material>Gazebo/Yellow</material>
  </gazebo>
  <link name="lh_upper_leg_link">
    <inertial>
      <origin xyz="0 0 -0.002375000000000002"/>
      <mass value="0.0625"/>
      <inertia ixx="3.159338020833334e-05" ixy="0.0" ixz="0.0" iyy="3.7282633854166664e-05" iyz="0.0" izz="7.931013020833332e-06"/>
    </inertial>
    <collision>
      <origin rpy="0 0 0" xyz="0 0 0"/>
      <geometry>
        <mesh filename="../meshes/lh_lower_leg.stl" scale="1 1 1"/>
      </geometry>
    </collision>
    <visual>
      <origin rpy="0 0 0" xyz="0 0 0"/>
      <geometry>
        <mesh filename="../meshes/lh_lower_leg.stl" scale="1 1 1"/>
      </geometry>
      <material name="dyellow"/>
    </visual>
  </link>
  <gazebo reference="lh_upper_leg_link">
    <material>Gazebo/Yellow</material>
  </gazebo>
  <link name="lh_lower_leg_link">
    <inertial>
      <origin xyz="0 0 -0.016780000000000003"/>
      <mass value="0.125"/>
      <inertia ixx="6.411545416666666e-05" ixy="0.0" ixz="0.0" iyy="6.491712083333332e-05" iyz="0.0" izz="8.485416666666666e-07"/>
    </inertial>
    <collision>
      <origin rpy="0 0 0" xyz="0 0 0"/>
      <geometry>
        <mesh filename="../meshes/lh_lower_leg.stl" scale="1 1 1"/>
      </geometry>
    </collision>
    <visual>
      <origin rpy="0 0 0" xyz="0 0 0"/>
      <geometry>
        <mesh filename="../meshes/lh_lower_leg.stl" scale="1 1 1"/>
      </geometry>
      <material name="black"/>
    </visual>
  </link>
  <gazebo reference="lh_lower_leg_link">
    <kp>1000000.0</kp>
    <kd>1.0</kd>
    <mu1>0.8</mu1>
    <mu2>0.8</mu2>
    <maxVel>0.0</maxVel>
    <minDepth>0.001</minDepth>
    <material>Gazebo/FlatBlack</material>
  </gazebo>
  <link name="lh_foot_link">
    <inertial>
      <origin xyz="0 0 0"/>
      <mass value="0.0625"/>
      <inertia ixx="2.41921875e-06" ixy="0.0" ixz="0.0" iyy="3.7369270833333336e-06" iyz="0.0" izz="1.6927083333333335e-06"/>
    </inertial>
    <collision>
      <origin rpy="0 0 0" xyz="0 0 0"/>
      <geometry>
        <mesh filename="../meshes/foot.stl" scale="1 1 1"/>
      </geometry>
    </collision>
    <visual>
      <origin rpy="0 0 0" xyz="0 0 0"/>
      <geometry>
        <mesh filename="../meshes/foot.stl" scale="1 1 1"/>
      </geometry>
      <material name="black"/>
    </visual>
  </link>
  <gazebo reference="lh_foot_link">
    <material>Gazebo/FlatBlack</material>
  </gazebo>
  <joint name="lh_debug_joint" type="fixed">
    <parent link="base_link"/>
    <child link="lh_hip_debug_link"/>
    <origin rpy="0 0 0" xyz="-0.05886 0.0235 0.0171"/>
  </joint>
  <joint name="lh_hip_joint" type="revolute">
    <axis xyz="1 0 0"/>
    <limit effort="5" lower="-3.141592653589793" upper="3.141592653589793" velocity="2.5"/>
    <parent link="base_link"/>
    <child link="lh_hip_link"/>
    <origin rpy="0 0 0" xyz="-0.05886 0.0235 0.0171"/>
  </joint>
  <joint name="lh_upper_leg_joint" type="revolute">
    <axis xyz="0 1 0"/>
    <limit effort="5" lower="-3.141592653589793" upper="3.141592653589793" velocity="2.5"/>
    <parent link="lh_hip_link"/>
    <child link="lh_upper_leg_link"/>
    <origin rpy="0 0 0" xyz="0 0.0197 0"/>
  </joint>
  <joint name="lh_lower_leg_joint" type="revolute">
    <axis xyz="0 1 0"/>
    <limit effort="5" lower="-3.141592653589793" upper="3.141592653589793" velocity="2.5"/>
    <parent link="lh_upper_leg_link"/>
    <child link="lh_lower_leg_link"/>
    <origin rpy="0 0 0" xyz="0 0.00475 -0.05"/>
  </joint>
  <joint name="lh_foot_joint" type="fixed">
    <parent link="lh_lower_leg_link"/>
    <child link="lh_foot_link"/>
    <origin rpy="0 0 0" xyz="0 0 -0.056"/>
  </joint>
  <transmission name="lh_hip_joint_trans">
    <type>transmission_interface/SimpleTransmission</type>
    <joint name="lh_hip_joint">
      <hardwareInterface>hardware_interface/EffortJointInterface</hardwareInterface>
    </joint>
    <actuator name="lh_hip_joint_motor">
      <hardwareInterface>hardware_interface/EffortJointInterface</hardwareInterface>
      <mechanicalReduction>1</mechanicalReduction>
    </actuator>
  </transmission>
  <transmission name="lh_upper_leg_joint_trans">
    <type>transmission_interface/SimpleTransmission</type>
    <joint name="lh_upper_leg_joint">
      <hardwareInterface>hardware_interface/EffortJointInterface</hardwareInterface>
    </joint>
    <actuator name="lh_upper_leg_joint_motor">
      <hardwareInterface>hardware_interface/EffortJointInterface</hardwareInterface>
      <mechanicalReduction>1</mechanicalReduction>
    </actuator>
  </transmission>
  <transmission name="lh_lower_leg_joint_trans">
    <type>transmission_interface/SimpleTransmission</type>
    <joint name="lh_lower_leg_joint">
      <hardwareInterface>hardware_interface/EffortJointInterface</hardwareInterface>
    </joint>
    <actuator name="lh_lower_joint_motor">
      <hardwareInterface>hardware_interface/EffortJointInterface</hardwareInterface>
      <mechanicalReduction>1</mechanicalReduction>
    </actuator>
  </transmission>
  <link name="rf_hip_debug_link"/>
  <link name="rf_hip_link">
    <inertial>
      <mass value="0.25"/>
      <inertia ixx="7.298104166666667e-05" ixy="0.0" ixz="0.0" iyy="8.328208333333335e-05" iyz="0.0" izz="8.450270833333332e-05"/>
    </inertial>
    <collision>
      <origin rpy="0 0 0" xyz="0 0 0"/>
      <geometry>
        <mesh filename="../meshes/rf_hip.stl" scale="1 1 1"/>
      </geometry>
    </collision>
    <visual>
      <origin rpy="0 0 0" xyz="0 0 0"/>
      <geometry>
        <mesh filename="../meshes/rf_hip.stl" scale="1 1 1"/>
      </geometry>
      <material name="dyellow"/>
    </visual>
  </link>
  <gazebo reference="rf_hip_link">
    <material>Gazebo/Yellow</material>
  </gazebo>
  <link name="rf_upper_leg_link">
    <inertial>
      <origin xyz="0 0 -0.002375000000000002"/>
      <mass value="0.0625"/>
      <inertia ixx="3.159338020833334e-05" ixy="0.0" ixz="0.0" iyy="3.7282633854166664e-05" iyz="0.0" izz="7.931013020833332e-06"/>
    </inertial>
    <collision>
      <origin rpy="0 0 0" xyz="0 0 0"/>
      <geometry>
        <mesh filename="../meshes/rf_lower_leg.stl" scale="1 1 1"/>
      </geometry>
    </collision>
    <visual>
      <origin rpy="0 0 0" xyz="0 0 0"/>
      <geometry>
        <mesh filename="../meshes/rf_lower_leg.stl" scale="1 1 1"/>
      </geometry>
      <material name="dyellow"/>
    </visual>
  </link>
  <gazebo reference="rf_upper_leg_link">
    <material>Gazebo/Yellow</material>
  </gazebo>
  <link name="rf_lower_leg_link">
    <inertial>
      <origin xyz="0 0 -0.016780000000000003"/>
      <mass value="0.125"/>
      <inertia ixx="6.411545416666666e-05" ixy="0.0" ixz="0.0" iyy="6.491712083333332e-05" iyz="0.0" izz="8.485416666666666e-07"/>
    </inertial>
    <collision>
      <origin rpy="0 0 0" xyz="0 0 0"/>
      <geometry>
        <mesh filename="../meshes/rf_lower_leg.stl" scale="1 1 1"/>
      </geometry>
    </collision>
    <visual>
      <origin rpy="0 0 0" xyz="0 0 0"/>
      <geometry>
        <mesh filename="../meshes/rf_lower_leg.stl" scale="1 1 1"/>
      </geometry>
      <material name="black"/>
    </visual>
  </link>
  <gazebo reference="rf_lower_leg_link">
    <kp>1000000.0</kp>
    <kd>1.0</kd>
    <mu1>0.8</mu1>
    <mu2>0.8</mu2>
    <maxVel>0.0</maxVel>
    <minDepth>0.001</minDepth>
    <material>Gazebo/FlatBlack</material>
  </gazebo>
  <link name="rf_foot_link">
    <inertial>
      <origin xyz="0 0 0"/>
      <mass value="0.0625"/>
      <inertia ixx="2.41921875e-06" ixy="0.0" ixz="0.0" iyy="3.7369270833333336e-06" iyz="0.0" izz="1.6927083333333335e-06"/>
    </inertial>
    <collision>
      <origin rpy="0 0 0" xyz="0 0 0"/>
      <geometry>
        <mesh filename="../meshes/foot.stl" scale="1 1 1"/>
      </geometry>
    </collision>
    <visual>
      <origin rpy="0 0 0" xyz="0 0 0"/>
      <geometry>
        <mesh filename="../meshes/foot.stl" scale="1 1 1"/>
      </geometry>
      <material name="black"/>
    </visual>
  </link>
  <gazebo reference="rf_foot_link">
    <material>Gazebo/FlatBlack</material>
  </gazebo>
  <joint name="rf_debug_joint" type="fixed">
    <parent link="base_link"/>
    <child link="rf_hip_debug_link"/>
    <origin rpy="0 0 0" xyz="0.06014 -0.0235 0.0171"/>
  </joint>
  <joint name="rf_hip_joint" type="revolute">
    <axis xyz="1 0 0"/>
    <limit effort="5" lower="-3.141592653589793" upper="3.141592653589793" velocity="2.5"/>
    <parent link="base_link"/>
    <child link="rf_hip_link"/>
    <origin rpy="0 0 0" xyz="0.06014 -0.0235 0.0171"/>
  </joint>
  <joint name="rf_upper_leg_joint" type="revolute">
    <axis xyz="0 1 0"/>
    <limit effort="5" lower="-3.141592653589793" upper="3.141592653589793" velocity="2.5"/>
    <parent link="rf_hip_link"/>
    <child link="rf_upper_leg_link"/>
    <origin rpy="0 0 0" xyz="0 -0.0197 0"/>
  </joint>
  <joint name="rf_lower_leg_joint" type="revolute">
    <axis xyz="0 1 0"/>
    <limit effort="5" lower="-3.141592653589793" upper="3.141592653589793" velocity="2.5"/>
    <parent link="rf_upper_leg_link"/>
    <child link="rf_lower_leg_link"/>
    <origin rpy="0 0 0" xyz="0 -0.00475 -0.05"/>
  </joint>
  <joint name="rf_foot_joint" type="fixed">
    <parent link="rf_lower_leg_link"/>
    <child link="rf_foot_link"/>
    <origin rpy="0 0 0" xyz="0 0 -0.056"/>
  </joint>
  <transmission name="rf_hip_joint_trans">
    <type>transmission_interface/SimpleTransmission</type>
    <joint name="rf_hip_joint">
      <hardwareInterface>hardware_interface/EffortJointInterface</hardwareInterface>
    </joint>
    <actuator name="rf_hip_joint_motor">
      <hardwareInterface>hardware_interface/EffortJointInterface</hardwareInterface>
      <mechanicalReduction>1</mechanicalReduction>
    </actuator>
  </transmission>
  <transmission name="rf_upper_leg_joint_trans">
    <type>transmission_interface/SimpleTransmission</type>
    <joint name="rf_upper_leg_joint">
      <hardwareInterface>hardware_interface/EffortJointInterface</hardwareInterface>
    </joint>
    <actuator name="rf_upper_leg_joint_motor">
      <hardwareInterface>hardware_interface/EffortJointInterface</hardwareInterface>
      <mechanicalReduction>1</mechanicalReduction>
    </actuator>
  </transmission>
  <transmission name="rf_lower_leg_joint_trans">
    <type>transmission_interface/SimpleTransmission</type>
    <joint name="rf_lower_leg_joint">
      <hardwareInterface>hardware_interface/EffortJointInterface</hardwareInterface>
    </joint>
    <actuator name="rf_lower_joint_motor">
      <hardwareInterface>hardware_interface/EffortJointInterface</hardwareInterface>
      <mechanicalReduction>1</mechanicalReduction>
    </actuator>
  </transmission>
  <link name="rh_hip_debug_link"/>
  <link name="rh_hip_link">
    <inertial>
      <mass value="0.25"/>
      <inertia ixx="7.298104166666667e-05" ixy="0.0" ixz="0.0" iyy="8.328208333333335e-05" iyz="0.0" izz="8.450270833333332e-05"/>
    </inertial>
    <collision>
      <origin rpy="0 0 0" xyz="0 0 0"/>
      <geometry>
        <mesh filename="../meshes/rh_hip.stl" scale="1 1 1"/>
      </geometry>
    </collision>
    <visual>
      <origin rpy="0 0 0" xyz="0 0 0"/>
      <geometry>
        <mesh filename="../meshes/rh_hip.stl" scale="1 1 1"/>
      </geometry>
      <material name="dyellow"/>
    </visual>
  </link>
  <gazebo reference="rh_hip_link">
    <material>Gazebo/Yellow</material>
  </gazebo>
  <link name="rh_upper_leg_link">
    <inertial>
      <origin xyz="0 0 -0.002375000000000002"/>
      <mass value="0.0625"/>
      <inertia ixx="3.159338020833334e-05" ixy="0.0" ixz="0.0" iyy="3.7282633854166664e-05" iyz="0.0" izz="7.931013020833332e-06"/>
    </inertial>
    <collision>
      <origin rpy="0 0 0" xyz="0 0 0"/>
      <geometry>
        <mesh filename="../meshes/rh_lower_leg.stl" scale="1 1 1"/>
      </geometry>
    </collision>
    <visual>
      <origin rpy="0 0 0" xyz="0 0 0"/>
      <geometry>
        <mesh filename="../meshes/rh_lower_leg.stl" scale="1 1 1"/>
      </geometry>
      <material name="dyellow"/>
    </visual>
  </link>
  <gazebo reference="rh_upper_leg_link">
    <material>Gazebo/Yellow</material>
  </gazebo>
  <link name="rh_lower_leg_link">
    <inertial>
      <origin xyz="0 0 -0.016780000000000003"/>
      <mass value="0.125"/>
      <inertia ixx="6.411545416666666e-05" ixy="0.0" ixz="0.0" iyy="6.491712083333332e-05" iyz="0.0" izz="8.485416666666666e-07"/>
    </inertial>
    <collision>
      <origin rpy="0 0 0" xyz="0 0 0"/>
      <geometry>
        <mesh filename="../meshes/rh_lower_leg.stl" scale="1 1 1"/>
      </geometry>
    </collision>
    <visual>
      <origin rpy="0 0 0" xyz="0 0 0"/>
      <geometry>
        <mesh filename="../meshes/rh_lower_leg.stl" scale="1 1 1"/>
      </geometry>
      <material name="black"/>
    </visual>
  </link>
  <gazebo reference="rh_lower_leg_link">
    <kp>1000000.0</kp>
    <kd>1.0</kd>
    <mu1>0.8</mu1>
    <mu2>0.8</mu2>
    <maxVel>0.0</maxVel>
    <minDepth>0.001</minDepth>
    <material>Gazebo/FlatBlack</material>
  </gazebo>
  <link name="rh_foot_link">
    <inertial>
      <origin xyz="0 0 0"/>
      <mass value="0.0625"/>
      <inertia ixx="2.41921875e-06" ixy="0.0" ixz="0.0" iyy="3.7369270833333336e-06" iyz="0.0" izz="1.6927083333333335e-06"/>
    </inertial>
    <collision>
      <origin rpy="0 0 0" xyz="0 0 0"/>
      <geometry>
        <mesh filename="../meshes/foot.stl" scale="1 1 1"/>
      </geometry>
    </collision>
    <visual>
      <origin rpy="0 0 0" xyz="0 0 0"/>
      <geometry>
        <mesh filename="../meshes/foot.stl" scale="1 1 1"/>
      </geometry>
      <material name="black"/>
    </visual>
  </link>
  <gazebo reference="rh_foot_link">
    <material>Gazebo/FlatBlack</material>
  </gazebo>
  <joint name="rh_debug_joint" type="fixed">
    <parent link="base_link"/>
    <child link="rh_hip_debug_link"/>
    <origin rpy="0 0 0" xyz="-0.05886 -0.0235 0.0171"/>
  </joint>
  <joint name="rh_hip_joint" type="revolute">
    <axis xyz="1 0 0"/>
    <limit effort="5" lower="-3.141592653589793" upper="3.141592653589793" velocity="2.5"/>
    <parent link="base_link"/>
    <child link="rh_hip_link"/>
    <origin rpy="0 0 0" xyz="-0.05886 -0.0235 0.0171"/>
  </joint>
  <joint name="rh_upper_leg_joint" type="revolute">
    <axis xyz="0 1 0"/>
    <limit effort="5" lower="-3.141592653589793" upper="3.141592653589793" velocity="2.5"/>
    <parent link="rh_hip_link"/>
    <child link="rh_upper_leg_link"/>
    <origin rpy="0 0 0" xyz="0 -0.0197 0"/>
  </joint>
  <joint name="rh_lower_leg_joint" type="revolute">
    <axis xyz="0 1 0"/>
    <limit effort="5" lower="-3.141592653589793" upper="3.141592653589793" velocity="2.5"/>
    <parent link="rh_upper_leg_link"/>
    <child link="rh_lower_leg_link"/>
    <origin rpy="0 0 0" xyz="0 -0.00475 -0.05"/>
  </joint>
  <joint name="rh_foot_joint" type="fixed">
    <parent link="rh_lower_leg_link"/>
    <child link="rh_foot_link"/>
    <origin rpy="0 0 0" xyz="0 0 -0.056"/>
  </joint>
  <transmission name="rh_hip_joint_trans">
    <type>transmission_interface/SimpleTransmission</type>
    <joint name="rh_hip_joint">
      <hardwareInterface>hardware_interface/EffortJointInterface</hardwareInterface>
    </joint>
    <actuator name="rh_hip_joint_motor">
      <hardwareInterface>hardware_interface/EffortJointInterface</hardwareInterface>
      <mechanicalReduction>1</mechanicalReduction>
    </actuator>
  </transmission>
  <transmission name="rh_upper_leg_joint_trans">
    <type>transmission_interface/SimpleTransmission</type>
    <joint name="rh_upper_leg_joint">
      <hardwareInterface>hardware_interface/EffortJointInterface</hardwareInterface>
    </joint>
    <actuator name="rh_upper_leg_joint_motor">
      <hardwareInterface>hardware_interface/EffortJointInterface</hardwareInterface>
      <mechanicalReduction>1</mechanicalReduction>
    </actuator>
  </transmission>
  <transmission name="rh_lower_leg_joint_trans">
    <type>transmission_interface/SimpleTransmission</type>
    <joint name="rh_lower_leg_joint">
      <hardwareInterface>hardware_interface/EffortJointInterface</hardwareInterface>
    </joint>
    <actuator name="rh_lower_joint_motor">
      <hardwareInterface>hardware_interface/EffortJointInterface</hardwareInterface>
      <mechanicalReduction>1</mechanicalReduction>
    </actuator>
  </transmission>
  <gazebo>
    <plugin filename="libgazebo_ros_p3d.so" name="p3d_base_controller">
      <alwaysOn>true</alwaysOn>
      <updateRate>10.0</updateRate>
      <bodyName>base_link</bodyName>
      <topicName>odom/ground_truth</topicName>
      <gaussianNoise>0.01</gaussianNoise>
      <frameName>world</frameName>
      <xyzOffsets>0 0 0</xyzOffsets>
      <rpyOffsets>0 0 0</rpyOffsets>
    </plugin>
  </gazebo>
  <gazebo>
    <plugin filename="libgazebo_ros_control.so" name="gazebo_ros_control">
      <legacyModeNS>true</legacyModeNS>
    </plugin>
  </gazebo>
</robot>
